2020-11-17 22:13:12,594 -- run.py -- this is file error
Traceback (most recent call last):
  File "/home/mohadese/PycharmProjects/sales_ticket/run.py", line 30, in show_detail
    with open("eventss.csv", mode='r') as csv_file:
FileNotFoundError: [Errno 2] No such file or directory: 'eventss.csv'
2020-11-18 14:50:30,358 -- user.py -- this is file error
Traceback (most recent call last):
  File "/home/mohadese/PycharmProjects/sales_ticket/user.py", line 30, in show_detail
    with open("eventss.csv", mode='r') as csv_file:
FileNotFoundError: [Errno 2] No such file or directory: 'eventss.csv'
2020-11-18 18:02:54,205 -- user.py -- this is file error
Traceback (most recent call last):
  File "/home/mohadese/PycharmProjects/sales_ticket/user.py", line 33, in show_detail
    (movies[user_input][2]))
IndexError: list index out of range
2020-11-19 22:25:58,242 -- user.py -- this is file error
Traceback (most recent call last):
  File "/home/mohadese/PycharmProjects/sales_ticket/user.py", line 25, in show_event
    df_first_2["Cost_event"] = df_first_2["Cost_event"].astype(int)
  File "/home/mohadese/virtualEnvironments/sales_ticket/lib/python3.8/site-packages/pandas/core/generic.py", line 5546, in astype
    new_data = self._mgr.astype(dtype=dtype, copy=copy, errors=errors,)
  File "/home/mohadese/virtualEnvironments/sales_ticket/lib/python3.8/site-packages/pandas/core/internals/managers.py", line 595, in astype
    return self.apply("astype", dtype=dtype, copy=copy, errors=errors)
  File "/home/mohadese/virtualEnvironments/sales_ticket/lib/python3.8/site-packages/pandas/core/internals/managers.py", line 406, in apply
    applied = getattr(b, f)(**kwargs)
  File "/home/mohadese/virtualEnvironments/sales_ticket/lib/python3.8/site-packages/pandas/core/internals/blocks.py", line 595, in astype
    values = astype_nansafe(vals1d, dtype, copy=True)
  File "/home/mohadese/virtualEnvironments/sales_ticket/lib/python3.8/site-packages/pandas/core/dtypes/cast.py", line 974, in astype_nansafe
    return lib.astype_intsafe(arr.ravel(), dtype).reshape(arr.shape)
  File "pandas/_libs/lib.pyx", line 615, in pandas._libs.lib.astype_intsafe
ValueError: invalid literal for int() with base 10: '10$'
2020-11-19 23:56:31,450 -- user.py -- this is file error
Traceback (most recent call last):
  File "/home/mohadese/PycharmProjects/sales_ticket/user.py", line 40, in show_detail
    print(f"movie name :", (movies[user_input-1][1]), ", date_event:", (movies[user_input-1][2]), ", zarfiat:",
IndexError: list index out of range
2020-11-20 00:00:23,251 -- user.py -- this is file error
Traceback (most recent call last):
  File "/home/mohadese/PycharmProjects/sales_ticket/user.py", line 40, in show_detail
    print(f"movie name :", (movies[user_input][1]), ", date_event:", (movies[user_input][2]), ", zarfiat:",
IndexError: list index out of range
2020-11-20 00:00:36,413 -- user.py -- this is file error
Traceback (most recent call last):
  File "/home/mohadese/PycharmProjects/sales_ticket/user.py", line 40, in show_detail
    print(f"movie name :", (movies[user_input][1]), ", date_event:", (movies[user_input][2]), ", zarfiat:",
IndexError: list index out of range
2020-11-20 00:01:05,192 -- user.py -- this is file error
Traceback (most recent call last):
  File "/home/mohadese/PycharmProjects/sales_ticket/user.py", line 40, in show_detail
    print(f"movie name :", (movies[user_input][1]), ", date_event:", (movies[user_input][2]), ", zarfiat:",
IndexError: list index out of range
